Workbook

Sheet Portfolio
G2: Symbol | H2: Unit Margin | I2: Size | J2: Tot Margin | T2: Starting Capital | V2: 100000
G3: @ESU24 | H3: 12980 | I3: 0.5 | J3: =+I3*H3 -> 6490
G4: @GCQ24 | H4: 11000 | I4: 1 | J4: =+I4*H4 -> 11000 | T4: Total Profit | V4: =+K23 -> 388839.4 | W4: =+V4/V2 -> 3.888394
G5: @JYU24 | H5: 2800 | I5: 1 | J5: =+I5*H5 -> 2800 | T5: Total Years | V5: 5.5 | W5: =+W4/V5 -> 0.70698073
G6: @TYU24 | H6: 2338 | I6: 5 | J6: =+I6*H6 -> 11690 | T6: Max DrawDown (times x 1.3) | V6: =+M23*1.3 -> -30110.47 | W6: =+V6/V2 -> -0.3011047
J7: =+SUM(J3:J6) -> 31980 | T7: ROA (Return On Account) | V7: =-V4/V6 -> 12.913761
T9: Margin Required | V9: =+J7 -> 31980
T10: Minimum Capital | V10: =+V9-V6 -> 62090.47
G23: =+G1566 -> 112200 | H23: =+H1566 -> 68530 | I23: =+I1566 -> 93187.5 | J23: =+J1566 -> 114921.9 | K23: =+K1566 -> 388839.4 | M23: =+MIN(M24:M1566) -> -23161.9
A24: Date | B24: @ESU24 | C24: @GCQ24 | D24: @JYU24 | E24: @TYU24 | F24: Date | G24: =+B24 -> @ESU24 | H24: =+C24 -> @GCQ24 | I24: =+D24 -> @JYU24 | J24: =+E24 -> @TYU24 | K24: Global Equity | L24: Peak | M24: DrawDown
A25: 1190709 | B25: -193.75 | C25: 230 | D25: 68.75 | E25: 703.1 | F25: =+A25 -> 1190709 | G25: =+IF(B25<>0,B25,B24) -> -193.75 | H25: =+IF(C25<>0,C25,C24) -> 230 | I25: =+IF(D25<>0,D25,D24) -> 68.75 | J25: =+IF(E25<>0,E25,E24) -> 703.1 | K25: =+SUM(G25:J25) -> 808.1
A26: 1190710 | B26: 181.25 | C26: -50 | D26: -281.25 | E26: -937.5 | F26: =+A26 -> 1190710 | G26: =+IF(B26<>0,B26,B25) -> 181.25 | H26: =+IF(C26<>0,C26,C25) -> -50 | I26: =+IF(D26<>0,D26,D25) -> -281.25 | J26: =+IF(E26<>0,E26,E25) -> -937.5 | K26: =+SUM(G26:J26) -> -1087.5 | L26: =+IF(K26>K25,K26,K25) -> 808.1 | M26: =+K26-L26 -> -1895.6
A27: 1190711 | B27: 181.25 | C27: 2720 | D27: 668.75 | E27: 1250 | F27: =+A27 -> 1190711 | G27: =+IF(B27<>0,B27,B26) -> 181.25 | H27: =+IF(C27<>0,C27,C26) -> 2720 | I27: =+IF(D27<>0,D27,D26) -> 668.75 | J27: =+IF(E27<>0,E27,E26) -> 1250 | K27: =+SUM(G27:J27) -> 4820 | L27: =+IF(K27>K26,K27,K26) -> 4820 | M27: =+K27-L27 -> 0
A28: 1190712 | B28: -118.75 | C28: 3700 | D28: 518.75 | E28: 2656.25 | F28: =+A28 -> 1190712 | G28: =+IF(B28<>0,B28,B27) -> -118.75 | H28: =+IF(C28<>0,C28,C27) -> 3700 | I28: =+IF(D28<>0,D28,D27) -> 518.75 | J28: =+IF(E28<>0,E28,E27) -> 2656.25 | K28: =+SUM(G28:J28) -> 6756.25 | L28: =+IF(K28>K27,K28,K27) -> 6756.25 | M28: =+K28-L28 -> 0
A29: 1190714 | B29: -31.25 | C29: 3900 | D29: 843.75 | E29: 2031.25 | F29: =+A29 -> 1190714 | G29: =+IF(B29<>0,B29,B28) -> -31.25 | H29: =+IF(C29<>0,C29,C28) -> 3900 | I29: =+IF(D29<>0,D29,D28) -> 843.75 | J29: =+IF(E29<>0,E29,E28) -> 2031.25 | K29: =+SUM(G29:J29) -> 6743.75 | L29: =+IF(K29>K28,K29,K28) -> 6756.25 | M29: =+K29-L29 -> -12.5
A30: 1190715 | B30: 50 | C30: 3900 | D30: 668.75 | E30: 2734.4 | F30: =+A30 -> 1190715 | G30: =+IF(B30<>0,B30,B29) -> 50 | H30: =+IF(C30<>0,C30,C29) -> 3900 | I30: =+IF(D30<>0,D30,D29) -> 668.75 | J30: =+IF(E30<>0,E30,E29) -> 2734.4 | K30: =+SUM(G30:J30) -> 7353.15 | L30: =+IF(K30>K29,K30,K29) -> 7353.15 | M30: =+K30-L30 -> 0
A31: 1190716 | B31: -243.75 | C31: 3700 | D31: 662.5 | E31: 2890.6 | F31: =+A31 -> 1190716 | G31: =+IF(B31<>0,B31,B30) -> -243.75 | H31: =+IF(C31<>0,C31,C30) -> 3700 | I31: =+IF(D31<>0,D31,D30) -> 662.5 | J31: =+IF(E31<>0,E31,E30) -> 2890.6 | K31: =+SUM(G31:J31) -> 7009.35 | L31: =+IF(K31>K30,K31,K30) -> 7353.15 | M31: =+K31-L31 -> -343.8
A32: 1190717 | B32: 18.75 | C32: 4650 | D32: 906.25 | E32: 2187.5 | F32: =+A32 -> 1190717 | G32: =+IF(B32<>0,B32,B31) -> 18.75 | H32: =+IF(C32<>0,C32,C31) -> 4650 | I32: =+IF(D32<>0,D32,D31) -> 906.25 | J32: =+IF(E32<>0,E32,E31) -> 2187.5 | K32: =+SUM(G32:J32) -> 7762.5 | L32: =+IF(K32>K31,K32,K31) -> 7762.5 | M32: =+K32-L32 -> 0
A33: 1190718 | B33: 568.75 | C33: 5990 | D33: 1356.25 | E33: 3593.75 | F33: =+A33 -> 1190718 | G33: =+IF(B33<>0,B33,B32) -> 568.75 | H33: =+IF(C33<>0,C33,C32) -> 5990 | I33: =+IF(D33<>0,D33,D32) -> 1356.25 | J33: =+IF(E33<>0,E33,E32) -> 3593.75 | K33: =+SUM(G33:J33) -> 11508.75 | L33: =+IF(K33>K32,K33,K32) -> 11508.75 | M33: =+K33-L33 -> 0
A34: 1190719 | B34: 1081.25 | C34: 3140 | D34: 956.25 | E34: 1796.9 | F34: =+A34 -> 1190719 | G34: =+IF(B34<>0,B34,B33) -> 1081.25 | H34: =+IF(C34<>0,C34,C33) -> 3140 | I34: =+IF(D34<>0,D34,D33) -> 956.25 | J34: =+IF(E34<>0,E34,E33) -> 1796.9 | K34: =+SUM(G34:J34) -> 6974.4 | L34: =+IF(K34>K33,K34,K33) -> 11508.75 | M34: =+K34-L34 -> -4534.35
A35: 1190721 | B35: 1337.5 | C35: 4940 | D35: 950 | E35: 2656.25 | F35: =+A35 -> 1190721 | G35: =+IF(B35<>0,B35,B34) -> 1337.5 | H35: =+IF(C35<>0,C35,C34) -> 4940 | I35: =+IF(D35<>0,D35,D34) -> 950 | J35: =+IF(E35<>0,E35,E34) -> 2656.25 | K35: =+SUM(G35:J35) -> 9883.75 | L35: =+IF(K35>K34,K35,K34) -> 9883.75 | M35: =+K35-L35 -> 0
A36: 1190722 | B36: 1331.25 | C36: 4720 | D36: 1118.75 | E36: 2500 | F36: =+A36 -> 1190722 | G36: =+IF(B36<>0,B36,B35) -> 1331.25 | H36: =+IF(C36<>0,C36,C35) -> 4720 | I36: =+IF(D36<>0,D36,D35) -> 1118.75 | J36: =+IF(E36<>0,E36,E35) -> 2500 | K36: =+SUM(G36:J36) -> 9670 | L36: =+IF(K36>K35,K36,K35) -> 9883.75 | M36: =+K36-L36 -> -213.75
A37: 1190723 | B37: 1087.5 | C37: 4560 | D37: 1031.25 | E37: 1562.5 | F37: =+A37 -> 1190723 | G37: =+IF(B37<>0,B37,B36) -> 1087.5 | H37: =+IF(C37<>0,C37,C36) -> 4560 | I37: =+IF(D37<>0,D37,D36) -> 1031.25 | J37: =+IF(E37<>0,E37,E36) -> 1562.5 | K37: =+SUM(G37:J37) -> 8241.25 | L37: =+IF(K37>K36,K37,K36) -> 9670 | M37: =+K37-L37 -> -1428.75
... A564: 1210401 | B564: 29718.75 | C564: 62120 | D564: 31937.5 | E564: 43437.5 | F564: =+A564 -> 1210401 | G564: =+IF(B564<>0,B564,B563) -> 29718.75 | H564: =+IF(C564<>0,C564,C563) -> 62120 | I564: =+IF(D564<>0,D564,D563) -> 31937.5 | J564: =+IF(E564<>0,E564,E563) -> 43437.5 | K564: =+SUM(G564:J564) -> 167213.75 | L564: =+IF(K564>K563,K564,K563) -> 168679.35 | M564: =+K564-L564 -> -1465.6
A565: 1210402 | B565: 30925 | D565: 31881.25 | E565: 45000 | F565: =+A565 -> 1210402 | G565: =+IF(B565<>0,B565,B564) -> 30925 | H565: =+IF(C565<>0,C565,C564) -> 62120 | I565: =+IF(D565<>0,D565,D564) -> 31881.25 | J565: =+IF(E565<>0,E565,E564) -> 45000 | K565: =+SUM(G565:J565) -> 169926.25 | L565: =+IF(K565>K564,K565,K564) -> 169926.25 | M565: =+K565-L565 -> 0
A566: 1210404 | B566: 31125 | C566: 62510 | D566: 32075 | E566: 43515.6 | F566: =+A566 -> 1210404 | G566: =+IF(B566<>0,B566,B565) -> 31125 | H566: =+IF(C566<>0,C566,C565) -> 62510 | I566: =+IF(D566<>0,D566,D565) -> 32075 | J566: =+IF(E566<>0,E566,E565) -> 43515.6 | K566: =+SUM(G566:J566) -> 169225.6 | L566: =+IF(K566>K565,K566,K565) -> 169926.25 | M566: =+K566-L566 -> -700.65
A567: 1210405 | B567: 31250 | C567: 62510 | D567: 32006.25 | E567: 43906.25 | F567: =+A567 -> 1210405 | G567: =+IF(B567<>0,B567,B566) -> 31250 | H567: =+IF(C567<>0,C567,C566) -> 62510 | I567: =+IF(D567<>0,D567,D566) -> 32006.25 | J567: =+IF(E567<>0,E567,E566) -> 43906.25 | K567: =+SUM(G567:J567) -> 169672.5 | L567: =+IF(K567>K566,K567,K566) -> 169672.5 | M567: =+K567-L567 -> 0
A568: 1210406 | B568: 31487.5 | C568: 62990 | D568: 32225 | E568: 44218.75 | F568: =+A568 -> 1210406 | G568: =+IF(B568<>0,B568,B567) -> 31487.5 | H568: =+IF(C568<>0,C568,C567) -> 62990 | I568: =+IF(D568<>0,D568,D567) -> 32225 | J568: =+IF(E568<>0,E568,E567) -> 44218.75 | K568: =+SUM(G568:J568) -> 170921.25 | L568: =+IF(K568>K567,K568,K567) -> 170921.25 | M568: =+K568-L568 -> 0
A569: 1210407 | B569: 31625 | C569: 63750 | D569: 32775 | E569: 45546.9 | F569: =+A569 -> 1210407 | G569: =+IF(B569<>0,B569,B568) -> 31625 | H569: =+IF(C569<>0,C569,C568) -> 63750 | I569: =+IF(D569<>0,D569,D568) -> 32775 | J569: =+IF(E569<>0,E569,E568) -> 45546.9 | K569: =+SUM(G569:J569) -> 173696.9 | L569: =+IF(K569>K568,K569,K568) -> 173696.9 | M569: =+K569-L569 -> 0
A570: 1210408 | B570: 32143.75 | C570: 63510 | D570: 32381.25 | E570: 46015.6 | F570: =+A570 -> 1210408 | G570: =+IF(B570<>0,B570,B569) -> 32143.75 | H570: =+IF(C570<>0,C570,C569) -> 63510 | I570: =+IF(D570<>0,D570,D569) -> 32381.25 | J570: =+IF(E570<>0,E570,E569) -> 46015.6 | K570: =+SUM(G570:J570) -> 174050.6 | L570: =+IF(K570>K569,K570,K569) -> 174050.6 | M570: =+K570-L570 -> 0
A571: 1210409 | B571: 31318.75 | C571: 63080 | D571: 32687.5 | E571: 47265.6 | F571: =+A571 -> 1210409 | G571: =+IF(B571<>0,B571,B570) -> 31318.75 | H571: =+IF(C571<>0,C571,C570) -> 63080 | I571: =+IF(D571<>0,D571,D570) -> 32687.5 | J571: =+IF(E571<>0,E571,E570) -> 47265.6 | K571: =+SUM(G571:J571) -> 174351.85 | L571: =+IF(K571>K570,K571,K570) -> 174351.85 | M571: =+K571-L571 -> 0
A572: 1210411 | B572: 31656.25 | C572: 62360 | D572: 32287.5 | E572: 45312.5 | F572: =+A572 -> 1210411 | G572: =+IF(B572<>0,B572,B571) -> 31656.25 | H572: =+IF(C572<>0,C572,C571) -> 62360 | I572: =+IF(D572<>0,D572,D571) -> 32287.5 | J572: =+IF(E572<>0,E572,E571) -> 45312.5 | K572: =+SUM(G572:J572) -> 171616.25 | L572: =+IF(K572>K571,K572,K571) -> 174351.85 | M572: =+K572-L572 -> -2735.6
A573: 1210412 | B573: 31443.75 | C573: 62680 | D573: 32062.5 | E573: 44843.75 | F573: =+A573 -> 1210412 | G573: =+IF(B573<>0,B573,B572) -> 31443.75 | H573: =+IF(C573<>0,C573,C572) -> 62680 | I573: =+IF(D573<>0,D573,D572) -> 32062.5 | J573: =+IF(E573<>0,E573,E572) -> 44843.75 | K573: =+SUM(G573:J573) -> 171030 | L573: =+IF(K573>K572,K573,K572) -> 171616.25 | M573: =+K573-L573 -> -586.25
A574: 1210413 | B574: 31718.75 | C574: 61300 | D574: 31637.5 | E574: 46250 | F574: =+A574 -> 1210413 | G574: =+IF(B574<>0,B574,B573) -> 31718.75 | H574: =+IF(C574<>0,C574,C573) -> 61300 | I574: =+IF(D574<>0,D574,D573) -> 31637.5 | J574: =+IF(E574<>0,E574,E573) -> 46250 | K574: =+SUM(G574:J574) -> 170906.25 | L574: =+IF(K574>K573,K574,K573) -> 171030 | M574: =+K574-L574 -> -123.75
A575: 1210414 | B575: 32150 | C575: 61510 | D575: 31418.75 | E575: 47265.6 | F575: =+A575 -> 1210414 | G575: =+IF(B575<>0,B575,B574) -> 32150 | H575: =+IF(C575<>0,C575,C574) -> 61510 | I575: =+IF(D575<>0,D575,D574) -> 31418.75 | J575: =+IF(E575<>0,E575,E574) -> 47265.6 | K575: =+SUM(G575:J575) -> 172344.35 | L575: =+IF(K575>K574,K575,K574) -> 172344.35 | M575: =+K575-L575 -> 0
A576: 1210415 | B576: 31962.5 | C576: 60730 | D576: 31068.75 | E576: 45937.5 | F576: =+A576 -> 1210415 | G576: =+IF(B576<>0,B576,B575) -> 31962.5 | H576: =+IF(C576<>0,C576,C575) -> 60730 | I576: =+IF(D576<>0,D576,D575) -> 31068.75 | J576: =+IF(E576<>0,E576,E575) -> 45937.5 | K576: =+SUM(G576:J576) -> 169698.75 | L576: =+IF(K576>K575,K576,K575) -> 172344.35 | M576: =+K576-L576 -> -2645.6
A577: 1210416 | B577: 31637.5 | C577: 62320 | D577: 30912.5 | E577: 46406.25 | F577: =+A577 -> 1210416 | G577: =+IF(B577<>0,B577,B576) -> 31637.5 | H577: =+IF(C577<>0,C577,C576) -> 62320 | I577: =+IF(D577<>0,D577,D576) -> 30912.5 | J577: =+IF(E577<>0,E577,E576) -> 46406.25 | K577: =+SUM(G577:J577) -> 171276.25 | L577: =+IF(K577>K576,K577,K576) -> 171276.25 | M577: =+K577-L577 -> 0
... A1190: 1230406 | B1190: 66775 | C1190: 78150 | D1190: 81631.25 | E1190: 83671.9 | F1190: =+A1190 -> 1230406 | G1190: =+IF(B1190<>0,B1190,B1189) -> 66775 | H1190: =+IF(C1190<>0,C1190,C1189) -> 78150 | I1190: =+IF(D1190<>0,D1190,D1189) -> 81631.25 | J1190: =+IF(E1190<>0,E1190,E1189) -> 83671.9 | K1190: =+SUM(G1190:J1190) -> 310228.15 | L1190: =+IF(K1190>K1189,K1190,K1189) -> 310228.15 | M1190: =+K1190-L1190 -> 0
A1191: 1230407 | B1191: 66487.5 | D1191: 80856.25 | E1191: 82734.4 | F1191: =+A1191 -> 1230407 | G1191: =+IF(B1191<>0,B1191,B1190) -> 66487.5 | H1191: =+IF(C1191<>0,C1191,C1190) -> 78150 | I1191: =+IF(D1191<>0,D1191,D1190) -> 80856.25 | J1191: =+IF(E1191<>0,E1191,E1190) -> 82734.4 | K1191: =+SUM(G1191:J1191) -> 308228.15 | L1191: =+IF(K1191>K1190,K1191,K1190) -> 310228.15 | M1191: =+K1191-L1191 -> -2000
A1192: 1230409 | B1192: 66781.25 | C1192: 77290 | D1192: 80493.75 | E1192: 84843.75 | F1192: =+A1192 -> 1230409 | G1192: =+IF(B1192<>0,B1192,B1191) -> 66781.25 | H1192: =+IF(C1192<>0,C1192,C1191) -> 77290 | I1192: =+IF(D1192<>0,D1192,D1191) -> 80493.75 | J1192: =+IF(E1192<>0,E1192,E1191) -> 84843.75 | K1192: =+SUM(G1192:J1192) -> 309408.75 | L1192: =+IF(K1192>K1191,K1192,K1191) -> 309408.75 | M1192: =+K1192-L1192 -> 0
...

Sheet PrintLog
A1: Symbol | B1: Date | C1: Equity | D1: Size | E1: Equity_rec
A2: @TYU24 | B2: 1190709 | C2: 140.62 | D2: =+VLOOKUP(A2,Portfolio!$G$3:$I$6,3) -> 5 | E2: =+C2*D2 -> 703.1
A3: @TYU24 | B3: 1190710 | C3: -187.5 | D3: =+VLOOKUP(A3,Portfolio!$G$3:$I$6,3) -> 5 | E3: =+C3*D3 -> -937.5
A4: @TYU24 | B4: 1190711 | C4: 250 | D4: =+VLOOKUP(A4,Portfolio!$G$3:$I$6,3) -> 5 | E4: =+C4*D4 -> 1250 | G4: Formula in D2 | H4: =VLOOKUP(A2;Portfolio!$G$3:$I$6;3)
A5: @TYU24 | B5: 1190712 | C5: 531.25 | D5: =+VLOOKUP(A5,Portfolio!$G$3:$I$6,3) -> 5 | E5: =+C5*D5 -> 2656.25
A6: @TYU24 | B6: 1190714 | C6: 406.25 | D6: =+VLOOKUP(A6,Portfolio!$G$3:$I$6,3) -> 5 | E6: =+C6*D6 -> 2031.25 | G6: Formula in E2 | H6: =C2*D2
A7: @TYU24 | B7: 1190715 | C7: 546.88 | D7: =+VLOOKUP(A7,Portfolio!$G$3:$I$6,3) -> 5 | E7: =+C7*D7 -> 2734.4
A8: @TYU24 | B8: 1190716 | C8: 578.12 | D8: =+VLOOKUP(A8,Portfolio!$G$3:$I$6,3) -> 5 | E8: =+C8*D8 -> 2890.6
A9: @TYU24 | B9: 1190717 | C9: 437.5 | D9: =+VLOOKUP(A9,Portfolio!$G$3:$I$6,3) -> 5 | E9: =+C9*D9 -> 2187.5
A10: @TYU24 | B10: 1190718 | C10: 718.75 | D10: =+VLOOKUP(A10,Portfolio!$G$3:$I$6,3) -> 5 | E10: =+C10*D10 -> 3593.75
A11: @TYU24 | B11: 1190719 | C11: 359.38 | D11: =+VLOOKUP(A11,Portfolio!$G$3:$I$6,3) -> 5 | E11: =+C11*D11 -> 1796.9
A12: @TYU24 | B12: 1190721 | C12: 531.25 | D12: =+VLOOKUP(A12,Portfolio!$G$3:$I$6,3) -> 5 | E12: =+C12*D12 -> 2656.25
A13: @TYU24 | B13: 1190722 | C13: 500 | D13: =+VLOOKUP(A13,Portfolio!$G$3:$I$6,3) -> 5 | E13: =+C13*D13 -> 2500
A14: @TYU24 | B14: 1190723 | C14: 312.5 | D14: =+VLOOKUP(A14,Portfolio!$G$3:$I$6,3) -> 5 | E14: =+C14*D14 -> 1562.5
A15: @TYU24 | B15: 1190724 | C15: -125 | D15: =+VLOOKUP(A15,Portfolio!$G$3:$I$6,3) -> 5 | E15: =+C15*D15 -> -625
A16: @TYU24 | B16: 1190725 | C16: 46.88 | D16: =+VLOOKUP(A16,Portfolio!$G$3:$I$6,3) -> 5 | E16: =+C16*D16 -> 234.4
A17: @TYU24 | B17: 1190726 | C17: 234.38 | D17: =+VLOOKUP(A17,Portfolio!$G$3:$I$6,3) -> 5 | E17: =+C17*D17 -> 1171.9
A18: @TYU24 | B18: 1190728 | C18: 234.38 | D18: =+VLOOKUP(A18,Portfolio!$G$3:$I$6,3) -> 5 | E18: =+C18*D18 -> 1171.9
... A6167: @ESU24 | B6167: 1240621 | C6167: 224400 | D6167: =+VLOOKUP(A6167,Portfolio!$G$3:$I$6,3) -> 0.5 | E6167: =+C6167*D6167 -> 112200
